Workbook

Sheet Tổng quan
A1: BÁO CÁO TIẾN ĐỘ PHÁT TRIỂN HỆ THỐNG ERP SAO VIỆT NHẬT
A2: Ngày báo cáo: 13/10/2026. Phạm vi: toàn bộ phân hệ trên menu hệ thống.
A4: 1. Kết quả chung
B5: Số phân hệ | D5: =COUNTA(B14:B25) -> 12
B6: Số chức năng | D6: =D26 -> 59
B7: Chức năng đã chạy, đang hoàn thiện | D7: =E26 -> 58
B8: Chức năng đang làm | D8: =F26 -> 1
B9: Tiến độ chung toàn hệ thống | D9: =G26 -> 0.92995891
A12: 2. Tiến độ theo phân hệ
A13: STT | B13: Phân hệ | C13: Nội dung chính | D13: Số chức năng | E13: Đã chạy | F13: Đang làm | G13: % hoàn thành | H13: Trạng thái
A14: 1 | B14: Tổng quan | C14: Trang tự phục vụ của từng nhân viên: hồ sơ, phép, công, phiếu lương. | D14: =COUNTIF('Chi tiết chức năng'!$B$5:$B$63,B14) -> 1 | E14: =COUNTIFS('Chi tiết chức năng'!$B$5:$B$63,B14,'Chi tiết chức năng'!$F$5:$F$63,">="&0.9) -> 1 | F14: =D14-E14 -> 0 | G14: =IF(D14=0,0,SUMIF('Chi tiết chức năng'!$B$5:$B$63,B14,'Chi tiết chức năng'!$F$5:$F$63)/D14) -> 0.97 | H14: =IF(F14>0,"Đang làm","Đang hoàn thiện") -> Đang hoàn thiện
A15: 2 | B15: Kinh doanh | C15: Từ tính giá, báo giá, đơn hàng tới giao hàng và chăm sóc khách. | D15: =COUNTIF('Chi tiết chức năng'!$B$5:$B$63,B15) -> 6 | E15: =COUNTIFS('Chi tiết chức năng'!$B$5:$B$63,B15,'Chi tiết chức năng'!$F$5:$F$63,">="&0.9) -> 6 | F15: =D15-E15 -> 0 | G15: =IF(D15=0,0,SUMIF('Chi tiết chức năng'!$B$5:$B$63,B15,'Chi tiết chức năng'!$F$5:$F$63)/D15) -> 0.93666667 | H15: =IF(F15>0,"Đang làm","Đang hoàn thiện") -> Đang hoàn thiện
A16: 3 | B16: Sản xuất | C16: Lên lệnh, xếp lịch máy, theo dõi đơn, kế hoạch vật tư, kiểm chất lượng. | D16: =COUNTIF('Chi tiết chức năng'!$B$5:$B$63,B16) -> 6 | E16: =COUNTIFS('Chi tiết chức năng'!$B$5:$B$63,B16,'Chi tiết chức năng'!$F$5:$F$63,">="&0.9) -> 6 | F16: =D16-E16 -> 0 | G16: =IF(D16=0,0,SUMIF('Chi tiết chức năng'!$B$5:$B$63,B16,'Chi tiết chức năng'!$F$5:$F$63)/D16) -> 0.91833333 | H16: =IF(F16>0,"Đang làm","Đang hoàn thiện") -> Đang hoàn thiện
A17: 4 | B17: Tổ sản xuất | C17: Bàn việc của từng tổ, bàn giao giữa tổ, ghi sản lượng theo mẻ. | D17: =COUNTIF('Chi tiết chức năng'!$B$5:$B$63,B17) -> 2 | E17: =COUNTIFS('Chi tiết chức năng'!$B$5:$B$63,B17,'Chi tiết chức năng'!$F$5:$F$63,">="&0.9) -> 2 | F17: =D17-E17 -> 0 | G17: =IF(D17=0,0,SUMIF('Chi tiết chức năng'!$B$5:$B$63,B17,'Chi tiết chức năng'!$F$5:$F$63)/D17) -> 0.925 | H17: =IF(F17>0,"Đang làm","Đang hoàn thiện") -> Đang hoàn thiện
A18: 5 | B18: Sửa chữa & bảo dưỡng | C18: Báo hỏng, phiếu sửa chữa, bảo trì định kỳ tự sinh. | D18: =COUNTIF('Chi tiết chức năng'!$B$5:$B$63,B18) -> 2 | E18: =COUNTIFS('Chi tiết chức năng'!$B$5:$B$63,B18,'Chi tiết chức năng'!$F$5:$F$63,">="&0.9) -> 2 | F18: =D18-E18 -> 0 | G18: =IF(D18=0,0,SUMIF('Chi tiết chức năng'!$B$5:$B$63,B18,'Chi tiết chức năng'!$F$5:$F$63)/D18) -> 0.97 | H18: =IF(F18>0,"Đang làm","Đang hoàn thiện") -> Đang hoàn thiện
A19: 6 | B19: Thu mua | C19: Yêu cầu mua, đơn mua gom theo nhà cung cấp, hồ sơ và bảng giá NCC. | D19: =COUNTIF('Chi tiết chức năng'!$B$5:$B$63,B19) -> 3 | E19: =COUNTIFS('Chi tiết chức năng'!$B$5:$B$63,B19,'Chi tiết chức năng'!$F$5:$F$63,">="&0.9) -> 3 | F19: =D19-E19 -> 0 | G19: =IF(D19=0,0,SUMIF('Chi tiết chức năng'!$B$5:$B$63,B19,'Chi tiết chức năng'!$F$5:$F$63)/D19) -> 0.91333333 | H19: =IF(F19>0,"Đang làm","Đang hoàn thiện") -> Đang hoàn thiện
A20: 7 | B20: Kế toán | C20: Duyệt đơn mua, phiếu thu chi, công nợ phải thu và phải trả, tài sản. | D20: =COUNTIF('Chi tiết chức năng'!$B$5:$B$63,B20) -> 7 | E20: =COUNTIFS('Chi tiết chức năng'!$B$5:$B$63,B20,'Chi tiết chức năng'!$F$5:$F$63,">="&0.9) -> 7 | F20: =D20-E20 -> 0 | G20: =IF(D20=0,0,SUMIF('Chi tiết chức năng'!$B$5:$B$63,B20,'Chi tiết chức năng'!$F$5:$F$63)/D20) -> 0.94857143 | H20: =IF(F20>0,"Đang làm","Đang hoàn thiện") -> Đang hoàn thiện
A21: 8 | B21: Kho hàng | C21: Yêu cầu nhập xuất, tồn theo lô và vị trí, cảnh báo và dự báo tồn. | D21: =COUNTIF('Chi tiết chức năng'!$B$5:$B$63,B21) -> 2 | E21: =COUNTIFS('Chi tiết chức năng'!$B$5:$B$63,B21,'Chi tiết chức năng'!$F$5:$F$63,">="&0.9) -> 2 | F21: =D21-E21 -> 0 | G21: =IF(D21=0,0,SUMIF('Chi tiết chức năng'!$B$5:$B$63,B21,'Chi tiết chức năng'!$F$5:$F$63)/D21) -> 0.97 | H21: =IF(F21>0,"Đang làm","Đang hoàn thiện") -> Đang hoàn thiện
A22: 9 | B22: Báo cáo | C22: Báo cáo kinh doanh, kho, công nợ, thu chi; bảng hoặc biểu đồ, xuất Excel. | D22: =COUNTIF('Chi tiết chức năng'!$B$5:$B$63,B22) -> 4 | E22: =COUNTIFS('Chi tiết chức năng'!$B$5:$B$63,B22,'Chi tiết chức năng'!$F$5:$F$63,">="&0.9) -> 4 | F22: =D22-E22 -> 0 | G22: =IF(D22=0,0,SUMIF('Chi tiết chức năng'!$B$5:$B$63,B22,'Chi tiết chức năng'!$F$5:$F$63)/D22) -> 0.955 | H22: =IF(F22>0,"Đang làm","Đang hoàn thiện") -> Đang hoàn thiện
A23: 10 | B23: Cấu hình danh mục | C23: 11 danh mục nền dùng chung; 9 danh mục nhập xuất được Excel. | D23: =COUNTIF('Chi tiết chức năng'!$B$5:$B$63,B23) -> 11 | E23: =COUNTIFS('Chi tiết chức năng'!$B$5:$B$63,B23,'Chi tiết chức năng'!$F$5:$F$63,">="&0.9) -> 11 | F23: =D23-E23 -> 0 | G23: =IF(D23=0,0,SUMIF('Chi tiết chức năng'!$B$5:$B$63,B23,'Chi tiết chức năng'!$F$5:$F$63)/D23) -> 0.93454545 | H23: =IF(F23>0,"Đang làm","Đang hoàn thiện") -> Đang hoàn thiện
A24: 11 | B24: Nhân sự & Lương | C24: Hồ sơ, chấm công GPS, phép, tăng ca, bảng lương, tạm ứng. Còn lương khoán sản phẩm. | D24: =COUNTIF('Chi tiết chức năng'!$B$5:$B$63,B24) -> 13 | E24: =COUNTIFS('Chi tiết chức năng'!$B$5:$B$63,B24,'Chi tiết chức năng'!$F$5:$F$63,">="&0.9) -> 12 | F24: =D24-E24 -> 1 | G24: =IF(D24=0,0,SUMIF('Chi tiết chức năng'!$B$5:$B$63,B24,'Chi tiết chức năng'!$F$5:$F$63)/D24) -> 0.90135198 | H24: =IF(F24>0,"Đang làm","Đang hoàn thiện") -> Đang làm
A25: 12 | B25: Quản lý hệ thống | C25: Phân quyền theo vai trò và phạm vi, nhật ký thao tác. | D25: =COUNTIF('Chi tiết chức năng'!$B$5:$B$63,B25) -> 2 | E25: =COUNTIFS('Chi tiết chức năng'!$B$5:$B$63,B25,'Chi tiết chức năng'!$F$5:$F$63,">="&0.9) -> 2 | F25: =D25-E25 -> 0 | G25: =IF(D25=0,0,SUMIF('Chi tiết chức năng'!$B$5:$B$63,B25,'Chi tiết chức năng'!$F$5:$F$63)/D25) -> 0.92 | H25: =IF(F25>0,"Đang làm","Đang hoàn thiện") -> Đang hoàn thiện
B26: TOÀN HỆ THỐNG | D26: =SUM(D14:D25) -> 59 | E26: =SUM(E14:E25) -> 58 | F26: =SUM(F14:F25) -> 1 | G26: =IF(D26=0,0,SUMPRODUCT(D14:D25,G14:G25)/D26) -> 0.92995891 | H26: =IF(F26>0,"Đang làm","Đang hoàn thiện") -> Đang làm
A28: 3. Đánh giá và việc còn lại
A29: 1 | B29: ="Đã có "&E26&"/"&D26&" chức năng của "&D5&" phân hệ chạy được trên hệ thống, tiến độ chung "&FIXED(G26*100,1)&"%." -> Đã có 58/59 chức năng của 12 phân hệ chạy được trên hệ thống, tiến độ chung 93,0%.
A30: 2 | B30: =COUNTIF(H14:H25,"Đang hoàn thiện")&"/"&D5&" phân hệ đã chạy đủ chức năng, đang kiểm thử và hoàn thiện. Phân hệ còn chức năng đang làm là Nhân sự & Lương ("&FIXED(G24*100,1)&"%), do còn phần tính lương khoán." -> 11/12 phân hệ đã chạy đủ chức năng, đang kiểm thử và hoàn thiện. Phân hệ còn chức năng đang làm là Nhân sự & Lương (90,1%), do còn phần tính lương khoán.
A31: 3 | B31: ="Tính lương khoán hiện đạt khoảng "&FIXED('Lương khoán'!$E$24*100,0)&"% (chi tiết ở sheet Lương khoán)." -> Tính lương khoán hiện đạt khoảng 56% (chi tiết ở sheet Lương khoán).
A32: 4 | B32: Đã có đầu vào (đơn giá khoán theo công đoạn, tổ ghi sản lượng theo mẻ kèm người làm) và đầu ra (cột khoán trên bảng lương, phiếu lương, lương bù lỗ). Khoán km cho lái xe giao hàng đã chạy.
A33: 5 | B33: Còn thiếu khâu ở giữa: màn Khoán theo kỳ để đổi sản lượng thành tiền và chia cho từng người. Vì vậy hiện chưa có tiền khoán sản phẩm nào lên bảng lương; tổ khoán đang được trả theo lương bù lỗ.
A35: 4. Cách tính
A36: • | B36: Chức năng đã chạy được tính từ 90% trở lên; phần còn lại dành cho kiểm thử với người dùng thật và chỉnh sửa sau khi đưa vào sử dụng.
A37: • | B37: Chức năng lấy theo các mục trên menu của hệ thống; màn Lương tách theo từng tab, phần tính lương khoán tách thành một dòng riêng.
A38: • | B38: % của một phân hệ = trung bình % các chức năng trong phân hệ. Toàn hệ thống = trung bình trên mọi chức năng.
A39: • | B39: % tính lương khoán = bình quân theo trọng số của 19 hạng mục ở sheet Lương khoán.
A40: • | B40: Nội dung đã làm được rà trực tiếp từ mã nguồn, không lấy từ tài liệu cũ.

Sheet Chi tiết chức năng
A1: CHI TIẾT CHỨC NĂNG THEO PHÂN HỆ
A2: Ngày báo cáo 13/10/2026. Cột F chữ xanh là ô nhập; chữ xanh lá lấy từ sheet Lương khoán.
A4: STT | B4: Phân hệ | C4: Chức năng | D4: Người dùng chính | E4: Những gì đã làm được | F4: % hoàn thành | G4: Trạng thái | H4: Ghi chú
A5: 1 | B5: Tổng quan | C5: Hồ sơ của tôi | D5: Mọi nhân viên | E5: • Xem hồ sơ cá nhân, ca làm hôm nay, thâm niên, quản lý trực tiếp • Tự sửa số điện thoại, email, người liên hệ khẩn cấp • Gửi đề nghị sửa thông tin cho HCNS duyệt, theo dõi hoặc rút lại • Xem nhanh phép năm còn lại, số công tháng này, phiếu lương gần nhất • Nhắc các mục hồ sơ còn thiếu; tự đổi ảnh đại diện và mật khẩu | F5: 0.97 | G5: =IF(F5>=0.9,"Đang hoàn thiện",IF(F5>0,"Đang làm","Chưa làm")) -> Đang hoàn thiện
A6: 2 | B6: Kinh doanh | C6: Quy trình kinh doanh | D6: Kinh doanh, nhân viên mới, Ban giám đốc | E6: • Sơ đồ 18 bước của một đơn, từ khách hỏi giá tới thu đủ tiền • Chia cột theo 7 bộ phận: Kinh doanh, Kế toán, KHSX, Tổ, KCS, Kho, Giao hàng • Mũi tên ghi rõ điều kiện chuyển bước (cần cọc, hàng đạt, kho đã nhận) • Bấm vào bước để xem mô tả và mở thẳng màn làm việc (theo quyền) | F6: 0.93 | G6: =IF(F6>=0.9,"Đang hoàn thiện",IF(F6>0,"Đang làm","Chưa làm")) -> Đang hoàn thiện
A7: 3 | B7: Kinh doanh | C7: Tính giá | D7: Kinh doanh | E7: • Phiếu tính giá vốn theo số lượng, nhiều sản phẩm và thành phần • Tự tính giấy, kẽm, mực, công in, gia công, bù hao từng công đoạn • Sơ đồ bình bài hiện ngay khi nhập, tự tính số con trên tờ in • Số liệu lấy từ danh mục, vẫn sửa tay được khi cần • Gọi lại cấu hình hàng tái bản; nhân bản sản phẩm hoặc cả phiếu • Chuyển phiếu sang báo giá bằng một nút | F7: 0.95 | G7: =IF(F7>=0.9,"Đang hoàn thiện",IF(F7>0,"Đang làm","Chưa làm")) -> Đang hoàn thiện
A8: 4 | B8: Kinh doanh | C8: Báo giá in ấn | D8: Kinh doanh, Giám đốc Kinh doanh (duyệt) | E8: • Lập báo giá từ phiếu tính giá, nhiều mức số lượng • Tự tính chiết khấu, VAT, giá bán, lợi nhuận; gõ tay giá từng dòng được • Báo giá đặc thù phải qua Giám đốc KD duyệt, bắt buộc ghi lý do • Quản lý phiên bản, bản cũ giữ trong lịch sử; đính kèm tệp • In hoặc lưu PDF trên giấy tiêu đề công ty • Ghi kết quả gửi khách; khách đồng ý thì lên đơn hàng ngay | F8: 0.97 | G8: =IF(F8>=0.9,"Đang hoàn thiện",IF(F8>0,"Đang làm","Chưa làm")) -> Đang hoàn thiện
A9: 5 | B9: Kinh doanh | C9: Đơn hàng bán | D9: Kinh doanh, Kế toán | E9: • Đơn sinh từ báo giá khách đã đồng ý, không gõ lại • Theo dõi cọc theo tỷ lệ: đã thu, còn thiếu, trừ cọc, trả cọc • Chốt đơn, ghi lưu ý sản xuất; đủ cọc thì tự chuyển xuống sản xuất • Xem các chặng của đơn: sản xuất, nhập kho, giao hàng, hóa đơn • Yêu cầu giao phần hàng đã nhập kho, giao từng phần được • Ghi hoặc hủy số hóa đơn MISA theo phần hàng đã giao | F9: 0.91 | G9: =IF(F9>=0.9,"Đang hoàn thiện",IF(F9>0,"Đang làm","Chưa làm")) -> Đang hoàn thiện
A10: 6 | B10: Kinh doanh | C10: Giao hàng | D10: Điều phối giao hàng, tài xế, Kho | E10: • Nhận yêu cầu giao, xếp xe, tài xế, phụ xe; gộp nhiều đơn một lượt • Báo kho soạn hàng kèm giờ cần xong; đổi hoặc hủy chuyến trước khi xuất • Ghi số đồng hồ xe lúc đi, tới khách, về kho; tự tính km • Ghi kết quả từng điểm giao kèm ảnh minh chứng • In phiếu xuất kho bán hàng và phiếu giao hàng theo mẫu MISA • Thống kê việc của từng tài xế theo tháng | F10: 0.96 | G10: =IF(F10>=0.9,"Đang hoàn thiện",IF(F10>0,"Đang làm","Chưa làm")) -> Đang hoàn thiện
A11: 7 | B11: Kinh doanh | C11: Khách hàng | D11: Kinh doanh, Trưởng phòng Kinh doanh | E11: • Danh bạ khách: lọc khách đang mua, ngừng đặt, chưa có đơn • Hồ sơ khách: doanh số 12 tháng, cơ cấu sản phẩm, tần suất, uy tín thanh toán • Lịch sử mua hàng, báo giá, công nợ của từng khách • Người liên hệ, địa chỉ giao hàng, thẻ phân loại; tra theo mã số thuế • Lịch hẹn chăm sóc khách, có nhắc khi tới hẹn • Chuyển khách hàng loạt sang nhân viên khác; nhập và xuất Excel | F11: 0.9 | G11: =IF(F11>=0.9,"Đang hoàn thiện",IF(F11>0,"Đang làm","Chưa làm")) -> Đang hoàn thiện
A12: 8 | B12: Sản xuất | C12: Kế hoạch sản xuất | D12: Phòng Kế hoạch sản xuất | E12: • Hàng chờ đơn Kinh doanh chuyển xuống, báo mức gấp và hạn giao • Lên lệnh từng món; món đủ tồn kho thì xuất kho, không cần lệnh • Hoàn thiện lệnh: quy cách, công đoạn, máy, số lượng, bù hao • Khai vật tư, giữ chỗ giấy trong kho, đính kèm maket và bản vẽ • Danh sách mục còn thiếu trước khi chuyển lệnh sang xếp lịch • Giao trọn gói hoặc từng công đoạn cho nhà gia công ngoài | F12: 0.93 | G12: =IF(F12>=0.9,"Đang hoàn thiện",IF(F12>0,"Đang làm","Chưa làm")) -> Đang hoàn thiện
A13: 9 | B13: Sản xuất | C13: Hồ sơ lệnh sản xuất | D13: Điều độ, QC, Kinh doanh (tra cứu) | E13: • Tra mọi lệnh đã phát hành, kể cả lệnh đã đóng • Các bước của lệnh trên một dòng, biết ngay đang ở bước nào • Sản lượng: số đặt, làm ra, KCS đạt, nhập kho, đã giao • Tổ, máy, giờ hẹn xong từng bước và các sự cố • Nhật ký đầy đủ của lệnh theo ngày | F13: 0.91 | G13: =IF(F13>=0.9,"Đang hoàn thiện",IF(F13>0,"Đang làm","Chưa làm")) -> Đang hoàn thiện | H13: Màn chỉ để xem, không hiện số tiền (chủ ý thiết kế).
A14: 10 | B14: Sản xuất | C14: Theo dõi sản xuất | D14: Kinh doanh, chủ xưởng | E14: • Mỗi đơn một dòng, hiện 4 chặng Lệnh, Sản xuất, Kho, Giao • Báo đơn đang làm gì, còn bao lâu tới hạn, đang vướng gì • Lọc nhanh đơn đang vướng, đang làm, chờ giao, đã giao đủ • Từng mặt hàng: số đặt, đã nhập kho, có sẵn trong tồn, đã giao • Nhật ký đơn: giao xưởng, KCS, sự cố, kho nhận, giao hàng | F14: 0.9 | G14: =IF(F14>=0.9,"Đang hoàn thiện",IF(F14>0,"Đang làm","Chưa làm")) -> Đang hoàn thiện | H14: Màn chỉ để xem (chủ ý thiết kế).
A15: 11 | B15: Sản xuất | C15: Kế hoạch vật tư | D15: Kế hoạch sản xuất, Thu mua | E15: • Đối chiếu nhu cầu vật tư với tồn kho, hàng đang về, phần đã cấp • Xem theo lệnh hoặc theo mặt hàng, lọc theo tình trạng • Tạo đề nghị mua điền sẵn, chuyển sang Thu mua • Giữ hoặc nhả hàng giữa các lệnh; hủy phiếu mua phải ghi lý do • Xuất Excel bảng vật tư | F15: 0.93 | G15: =IF(F15>=0.9,"Đang hoàn thiện",IF(F15>0,"Đang làm","Chưa làm")) -> Đang hoàn thiện
A16: 12 | B16: Sản xuất | C16: Xếp lịch | D16: Kế hoạch sản xuất (điều độ) | E16: • Lịch theo ngày và theo máy, tính cả ngày lễ, ngày làm bù • Kéo lệnh từ khay chờ thả vào ngày; tự tính giờ bắt đầu và giờ xong • Cảnh báo trước lệnh có nguy cơ trễ hạn giao • Phát hành lệnh xuống xưởng, thu hồi, so sánh các lần phát hành • Hoàn tác thao tác vừa làm; xem tình trạng vật tư ngay trên lịch | F16: 0.91 | G16: =IF(F16>=0.9,"Đang hoàn thiện",IF(F16>0,"Đang làm","Chưa làm")) -> Đang hoàn thiện
A17: 13 | B17: Sản xuất | C17: KCS | D17: Bộ phận KCS | E17: • Danh sách lệnh chờ kiểm, số đạt và số cần • Ghi lỗi ở công đoạn giữa theo tiêu chí, kèm số lỗi và ảnh • Kiểm đạt ở bước cuối rồi gửi phần hàng đạt sang kho • Truy lỗi phát sinh ở công đoạn nào, tổ nào • Báo cáo lỗi dạng bảng hoặc biểu đồ, so kỳ trước; xuất Excel • Đóng lệnh theo nhóm, mở lại được; đóng khi còn thiếu cần quyền riêng | F17: 0.93 | G17: =IF(F17>=0.9,"Đang hoàn thiện",IF(F17>0,"Đang làm","Chưa làm")) -> Đang hoàn thiện
A18: 14 | B18: Tổ sản xuất | C18: Bàn việc của tổ | D18: Tổ trưởng, công nhân | E18: • Menu tự hiện các tổ người dùng được xem, tổ con nằm dưới tổ cha • Mỗi tổ có bàn riêng: việc chờ, lịch theo ngày, danh sách việc • Bắt đầu, tạm dừng (ghi lý do), kết thúc việc; đổi máy giữa chừng • Bàn giao bán thành phẩm sang tổ sau, tổ nhận xác nhận số lượng • Báo sự cố máy cho tổ sửa chữa; đề nghị kho cấp vật tư • Có dấu báo việc mới; dùng được trên điện thoại | F18: 0.92 | G18: =IF(F18>=0.9,"Đang hoàn thiện",IF(F18>0,"Đang làm","Chưa làm")) -> Đang hoàn thiện
A19: 15 | B19: Tổ sản xuất | C19: Ghi sản lượng | D19: Tổ trưởng, quản đốc | E19: • Ghi sản lượng từng mẻ kèm danh sách người cùng làm • Thêm người tổ khác sang hỗ trợ ngay lúc ghi • Sửa số mẻ đã ghi; tổ nhận được báo để xác nhận lại • Bảng sản lượng theo khoảng ngày: lệnh, công đoạn, số lượng, người làm • Tách phần người tổ mình đi làm ở tổ khác, không cộng trùng | F19: 0.93 | G19: =IF(F19>=0.9,"Đang hoàn thiện",IF(F19>0,"Đang làm","Chưa làm")) -> Đang hoàn thiện | H19: Là thẻ trên bàn việc của tổ, không phải mục menu riêng.
A20: 16 | B20: Sửa chữa & bảo dưỡng | C20: Sửa chữa máy | D20: Tổ kỹ thuật; thợ đứng máy, tổ trưởng (báo hỏng) | E20: • Ai cũng gửi được yêu cầu báo máy hỏng, có mô tả triệu chứng • Tổ kỹ thuật thấy hàng chờ, nhận sửa hoặc từ chối kèm lý do • Phiếu sửa chữa có mức độ, gắn với máy và lệnh sản xuất • Tính thời gian máy dừng, thời gian sửa; cảnh báo quá hạn • Đóng phiếu phải có ít nhất một ảnh sau sửa; lưu lịch sử thao tác | F20: 0.97 | G20: =IF(F20>=0.9,"Đang hoàn thiện",IF(F20>0,"Đang làm","Chưa làm")) -> Đang hoàn thiện
A21: 17 | B21: Sửa chữa & bảo dưỡng | C21: Phiếu bảo trì | D21: Tổ kỹ thuật | E21: • Phiếu định kỳ tự sinh khi tới hạn theo lịch bảo trì của máy • Lịch tháng hiện phiếu thật lẫn kỳ dự kiến, bấm vào là tạo phiếu • Thêm việc bảo trì ngoài lịch hoặc đột xuất • Danh sách việc cần làm; đóng phiếu khi đủ ảnh và xong việc • Cảnh báo quá hạn; hủy hoặc mở lại phải ghi lý do; in phiếu | F21: 0.97 | G21: =IF(F21>=0.9,"Đang hoàn thiện",IF(F21>0,"Đang làm","Chưa làm")) -> Đang hoàn thiện
A22: 18 | B22: Thu mua | C22: Yêu cầu mua hàng | D22: Các phòng ban | E22: • Lập yêu cầu chọn vật tư từ danh mục, ghi số lượng và ngày cần • Ba loại mua: theo yêu cầu, mua tồn kho, mua cho lệnh sản xuất • Tự điền sẵn khi đi từ Tồn kho hoặc Kế hoạch vật tư • Theo dõi từng món: đã có đơn, đã về, đã nhập kho • Sửa, hủy, bỏ bớt từng món, có lịch sử; lọc theo kỳ; in phiếu | F22: 0.92 | G22: =IF(F22>=0.9,"Đang hoàn thiện",IF(F22>0,"Đang làm","Chưa làm")) -> Đang hoàn thiện
A23: 19 | B23: Thu mua | C23: Mua hàng | D23: Bộ phận Thu mua | E23: • Hộp yêu cầu chờ xử lý, cảnh báo yêu cầu quá ngày cần • Gom nhiều yêu cầu thành đơn mua, tự tách theo nhà cung cấp • Ghi đơn giá, chiết khấu, VAT, hợp đồng, tiền cọc, điều khoản thanh toán • Ghi từng đợt giao, số thực nhận, hóa đơn • Từ đợt giao bấm Nhập kho, phiếu nhập điền sẵn • Gửi duyệt sang Kế toán, hủy có lý do, in phiếu, xem lịch sử | F23: 0.9 | G23: =IF(F23>=0.9,"Đang hoàn thiện",IF(F23>0,"Đang làm","Chưa làm")) -> Đang hoàn thiện
A24: 20 | B24: Thu mua | C24: Nhà cung cấp | D24: Thu mua, Kế toán | E24: • Hồ sơ NCC: liên hệ, mã số thuế, nhóm hàng, có nhận gia công không • Bảng giá vật tư theo khổ, quy đổi về đơn vị gốc để so giá • Nhập và xuất bảng giá bằng Excel • Tự chấm sao theo tỷ lệ giao đúng hẹn • Hạn mức công nợ, số ngày cho nợ; lịch sử đơn mua | F24: 0.92 | G24: =IF(F24>=0.9,"Đang hoàn thiện",IF(F24>0,"Đang làm","Chưa làm")) -> Đang hoàn thiện
A25: 21 | B25: Kế toán | C25: Đơn mua hàng (duyệt) | D25: Giám đốc, Kế toán thanh toán | E25: • Nhận mọi đơn mua Thu mua gửi sang, lọc theo tình trạng hàng và tiền • Duyệt hoặc từ chối, từ chối bắt buộc ghi lý do • Nút Duyệt và lập chứng từ chi tiền trong một bước • Cảnh báo NCC vượt hạn mức công nợ (nhắc, không chặn) | F25: 0.93 | G25: =IF(F25>=0.9,"Đang hoàn thiện",IF(F25>0,"Đang làm","Chưa làm")) -> Đang hoàn thiện
A26: 22 | B26: Kế toán | C26: Phiếu chi | D26: Kế toán thanh toán, Thủ quỹ | E26: • Chi tiền mặt hoặc ủy nhiệm chi chuyển khoản • Chi nhiều đợt: cọc, một phần, thanh toán cuối; không chi vượt • Chi cho đơn mua, gia công ngoài, trả lại khách, khoản chi khác theo mục • Đính kèm ảnh hoặc PDF hóa đơn; nhắc phiếu thiếu chứng từ • In đúng mẫu 02-TT, có số tiền bằng chữ; đã chi chỉ hủy kèm lý do | F26: 0.92 | G26: =IF(F26>=0.9,"Đang hoàn thiện",IF(F26>0,"Đang làm","Chưa làm")) -> Đang hoàn thiện
A27: 23 | B27: Kế toán | C27: Công nợ phải trả | D27: Kế toán công nợ, Kế toán trưởng | E27: • Nợ từng NCC tự tính từ hàng đã giao trừ tiền đã chi • Chia theo tuổi nợ, đánh dấu quá hạn và vượt hạn mức • Trả nhiều đợt cùng lúc bằng một phiếu chi • Ghi nhận NCC hoàn tiền; xem sao kê và lịch sử trả | F27: 0.95 | G27: =IF(F27>=0.9,"Đang hoàn thiện",IF(F27>0,"Đang làm","Chưa làm")) -> Đang hoàn thiện
A28: 24 | B28: Kế toán | C28: Phiếu thu | D28: Kế toán thanh toán, Thủ quỹ | E28: • Thu cọc đơn bán, thu theo hóa đơn, thu khác (bán phế liệu) • Thu tiền thừa từ phiếu chi; ghi nhận NCC hoàn tiền • Thu tiền mặt hoặc ngân hàng (bắt buộc mã giao dịch) • Đính kèm ảnh, in mẫu 01-TT, hủy kèm lý do | F28: 0.96 | G28: =IF(F28>=0.9,"Đang hoàn thiện",IF(F28>0,"Đang làm","Chưa làm")) -> Đang hoàn thiện
A29: 25 | B29: Kế toán | C29: Công nợ phải thu | D29: Kế toán công nợ; Kinh doanh | E29: • Tính nợ từng khách theo từng hóa đơn bán • Chia theo tuổi nợ, đánh dấu quá hạn, lọc theo người phụ trách • Thu tiền theo hóa đơn ngay trên màn, sinh phiếu thu • Trả lại tiền cho khách đang dư; sao kê và lịch sử thu | F29: 0.96 | G29: =IF(F29>=0.9,"Đang hoàn thiện",IF(F29>0,"Đang làm","Chưa làm")) -> Đang hoàn thiện
A30: 26 | B30: Kế toán | C30: Tài khoản ngân hàng | D30: Kế toán trưởng, Thủ quỹ | E30: • Khai tài khoản ngân hàng công ty, đặt tài khoản mặc định • Tổng thu, tổng chi trong kỳ, so cùng kỳ năm trước • Xem và in sao kê từng tài khoản • Ngừng hoặc dùng lại tài khoản | F30: 0.95 | G30: =IF(F30>=0.9,"Đang hoàn thiện",IF(F30>0,"Đang làm","Chưa làm")) -> Đang hoàn thiện
A31: 27 | B31: Kế toán | C31: Tài sản & CCDC | D31: Kế toán tài sản | E31: • Thêm tài sản mới mua hoặc đang dùng từ trước • Tự phân loại TSCĐ hay CCDC theo ngưỡng 30 triệu • Tự tính khấu hao từng tháng và giá trị còn lại • Chuyển bộ phận, sửa chữa lớn, thôi dùng (có hoàn tác) • Bảng khấu hao tháng xuất Excel; lịch sử biến động từng tài sản | F31: 0.97 | G31: =IF(F31>=0.9,"Đang hoàn thiện",IF(F31>0,"Đang làm","Chưa làm")) -> Đang hoàn thiện
... A33: 29 | B33: Kho hàng | C33: Màn từng kho (tồn, lô, phiếu) | D33: Thủ kho, Quản lý kho | E33: • Tồn theo mặt hàng, mở xem từng lô, vị trí, hạn dùng • Mức tồn tối thiểu, tối đa; cảnh báo thiếu, vượt, sắp hết hạn • Dự báo tồn theo hàng sắp xuất và sắp về; từ hàng thiếu tạo yêu cầu mua • Chuyển hàng giữa các kho; in tem lô • Chỉ người có quyền mới thấy giá vốn | F33: 0.97 | G33: =IF(F33>=0.9,"Đang hoàn thiện",IF(F33>0,"Đang làm","Chưa làm")) -> Đang hoàn thiện
A34: 30 | B34: Báo cáo | C34: Báo cáo kinh doanh | D34: Giám đốc, Kinh doanh | E34: • Đơn đã chốt theo từng khách, tính theo ngày chốt • Sản phẩm, đơn giá, tổng tiền có VAT của từng đơn • Cọc phải thu và đã nhận; đã giao, còn phải giao, đã xuất hóa đơn, đã thu • Xem dạng bảng hoặc biểu đồ; xuất Excel | F34: 0.96 | G34: =IF(F34>=0.9,"Đang hoàn thiện",IF(F34>0,"Đang làm","Chưa làm")) -> Đang hoàn thiện | H34: Nhân viên KD chỉ thấy đơn của mình.
A35: 31 | B35: Báo cáo | C35: Báo cáo kho | D35: Kế toán kho | E35: • Nhập, xuất, tồn theo kỳ, giá bình quân cuối kỳ • Sổ chi tiết phiếu nhập xuất và sổ chuyển kho • Khóa kỳ kho, đã khóa thì chặn sửa phiếu cũ • Xuất Excel đúng mẫu MISA; xem dạng biểu đồ | F35: 0.97 | G35: =IF(F35>=0.9,"Đang hoàn thiện",IF(F35>0,"Đang làm","Chưa làm")) -> Đang hoàn thiện
A36: 32 | B36: Báo cáo | C36: Báo cáo công nợ | D36: Kế toán trưởng, Giám đốc | E36: • Nợ phải thu và phải trả theo kỳ: đầu kỳ, phát sinh, cuối kỳ • Chia nợ cuối kỳ theo hạn và tuổi nợ • Sổ chi tiết từng khách hoặc NCC; khóa và mở sổ kỳ • Xuất Excel mẫu MISA; xem dạng biểu đồ | F36: 0.96 | G36: =IF(F36>=0.9,"Đang hoàn thiện",IF(F36>0,"Đang làm","Chưa làm")) -> Đang hoàn thiện
A37: 33 | B37: Báo cáo | C37: Báo cáo thu chi | D37: Giám đốc, Kế toán trưởng | E37: • Thu và chi theo mục, chia cột theo tháng, có dòng chênh lệch • Xem theo người nhận hoặc người nộp; nêu rõ khoản chưa phân loại • Bấm vào số để xem các phiếu tạo nên số đó • Xem dạng bảng hoặc biểu đồ; xuất Excel | F37: 0.93 | G37: =IF(F37>=0.9,"Đang hoàn thiện",IF(F37>0,"Đang làm","Chưa làm")) -> Đang hoàn thiện
A38: 34 | B38: Cấu hình danh mục | C38: Thiết bị & Máy móc | D38: Kỹ thuật, Kế hoạch sản xuất | E38: • Hồ sơ máy: nhóm, hãng, model, số seri • Tốc độ trung bình, nhanh nhất, chậm nhất, thời gian chuẩn bị • Lịch bảo trì định kỳ cho từng máy; trạng thái máy lúc này • Nhân bản máy; nhập và xuất Excel | F38: 0.94 | G38: =IF(F38>=0.9,"Đang hoàn thiện",IF(F38>0,"Đang làm","Chưa làm")) -> Đang hoàn thiện
A39: 35 | B39: Cấu hình danh mục | C39: Công đoạn | D39: Kỹ thuật, Kế hoạch SX, Kinh doanh | E39: • Giai đoạn, tổ phụ trách, tổ mặc định khi lên lệnh • Máy chạy được công đoạn, công thức giá riêng theo máy • Công thức giá, cách tính bù hao (cố định hoặc theo bậc) • Vật tư tiêu hao, đơn giá khoán cho tổ; cờ cần khuôn bế • Nhân bản; nhập và xuất Excel | F39: 0.9 | G39: =IF(F39>=0.9,"Đang hoàn thiện",IF(F39>0,"Đang làm","Chưa làm")) -> Đang hoàn thiện
A40: 36 | B40: Cấu hình danh mục | C40: Đơn vị & quy đổi | D40: Kho, Mua hàng | E40: • Tạo đơn vị và quy đổi dạng 1 A = n B ngay tại chỗ • Quy đổi bằng số cố định hoặc công thức • Thấy đơn vị đang được bao nhiêu mặt hàng dùng; nhập và xuất Excel | F40: 0.92 | G40: =IF(F40>=0.9,"Đang hoàn thiện",IF(F40>0,"Đang làm","Chưa làm")) -> Đang hoàn thiện
A41: 37 | B41: Cấu hình danh mục | C41: Giấy | D41: Kho, Mua hàng, Kinh doanh | E41: • Định lượng, đơn vị tính chính và phụ (kg, tờ) • Đơn giá theo kg; công thức tiền giấy tự điền sẵn, sửa được • Khai giấy thay thế khi thiếu hàng; nhân bản; nhập và xuất Excel | F41: 0.96 | G41: =IF(F41>=0.9,"Đang hoàn thiện",IF(F41>0,"Đang làm","Chưa làm")) -> Đang hoàn thiện
A42: 38 | B42: Cấu hình danh mục | C42: Vật tư khác | D42: Kho, Mua hàng, Kỹ thuật | E42: • Đơn vị tính chính và phụ, thông số riêng (dài, rộng) • Công thức tính tiền và định mức tiêu hao từng vật tư • Báo ngay vật tư chưa có công thức; nhân bản; nhập và xuất Excel | F42: 0.93 | G42: =IF(F42>=0.9,"Đang hoàn thiện",IF(F42>0,"Đang làm","Chưa làm")) -> Đang hoàn thiện
...

Sheet Lương khoán
A1: TÍNH LƯƠNG KHOÁN — HIỆN TRẠNG CHI TIẾT
A2: Rà từ mã nguồn ngày 13/10/2026. Sửa cột E (% hoàn thành) và F (trọng số), ô tổng tự tính lại.
A4: STT | B4: Khâu | C4: Hạng mục | D4: Trạng thái | E4: % hoàn thành | F4: Trọng số | G4: Hiện trạng
A5: 1 | B5: Đầu vào | C5: Khai đơn giá khoán theo công đoạn | D5: =IF(E5>=1,"Đã xong",IF(E5>=0.8,"Gần xong",IF(E5=0,"Chưa làm","Làm dở"))) -> Đã xong | E5: 1 | F5: 2 | G5: Mỗi công đoạn khai được đơn vị và đơn giá khoán.
A6: 2 | B6: Đầu vào | C6: Khai việc phát sinh (thay kẽm, lên khuôn…) | D6: =IF(E6>=1,"Đã xong",IF(E6>=0.8,"Gần xong",IF(E6=0,"Chưa làm","Làm dở"))) -> Đã xong | E6: 1 | F6: 1 | G6: Khai theo công đoạn, chọn được khi ghi mẻ.
A7: 3 | B7: Đầu vào | C7: Công thức ra lượng khoán | D7: =IF(E7>=1,"Đã xong",IF(E7>=0.8,"Gần xong",IF(E7=0,"Chưa làm","Làm dở"))) -> Làm dở | E7: 0.3 | F7: 2 | G7: Nhập và lưu được công thức, chưa áp dụng tính tự động.
A8: 4 | B8: Đầu vào | C8: Quy đổi đơn vị (tờ sang m², nhịp…) | D8: =IF(E8>=1,"Đã xong",IF(E8>=0.8,"Gần xong",IF(E8=0,"Chưa làm","Làm dở"))) -> Làm dở | E8: 0.5 | F8: 1 | G8: Danh mục quy đổi đã có, chưa được gọi khi tính khoán.
A9: 5 | B9: Đầu vào | C9: Ghi sản lượng theo mẻ, giữ đơn giá lúc ghi | D9: =IF(E9>=1,"Đã xong",IF(E9>=0.8,"Gần xong",IF(E9=0,"Chưa làm","Làm dở"))) -> Đã xong | E9: 1 | F9: 2 | G9: Tổ ghi mẻ (tốt + hỏng); mẻ giữ đơn giá tại thời điểm ghi.
A10: 6 | B10: Đầu vào | C10: Ghi người tham gia từng mẻ | D10: =IF(E10>=1,"Đã xong",IF(E10>=0.8,"Gần xong",IF(E10=0,"Chưa làm","Làm dở"))) -> Đã xong | E10: 1 | F10: 1 | G10: Có danh sách người làm trong mẻ, kể cả người tổ khác sang hỗ trợ.
A11: 7 | B11: Khâu tính tiền | C11: Chia sản lượng và tiền khoán cho từng người | D11: =IF(E11>=1,"Đã xong",IF(E11>=0.8,"Gần xong",IF(E11=0,"Chưa làm","Làm dở"))) -> Chưa làm | E11: 0 | F11: 3 | G11: Theo chốt 18/09: tổ chỉ ghi nhận, việc chia chuyển về màn kế toán (chưa có).
A12: 8 | B12: Khâu tính tiền | C12: Thưởng hoặc ăn chia của tổ trưởng | D12: =IF(E12>=1,"Đã xong",IF(E12>=0.8,"Gần xong",IF(E12=0,"Chưa làm","Làm dở"))) -> Làm dở | E12: 0.5 | F12: 1 | G12: Khai được các mốc, chưa nối vào tính lương.
A13: 9 | B13: Khâu tính tiền | C13: Chỉ tiêu ngày của tổ khoán | D13: =IF(E13>=1,"Đã xong",IF(E13>=0.8,"Gần xong",IF(E13=0,"Chưa làm","Làm dở"))) -> Làm dở | E13: 0.5 | F13: 1 | G13: Khai được, chưa nối vào tính lương.
A14: 10 | B14: Khâu tính tiền | C14: Tổng hợp sản lượng theo kỳ lương | D14: =IF(E14>=1,"Đã xong",IF(E14>=0.8,"Gần xong",IF(E14=0,"Chưa làm","Làm dở"))) -> Làm dở | E14: 0.4 | F14: 2 | G14: Có bảng sản lượng tổ theo ngày; chưa có tổng theo từng người trong kỳ lương.
A15: 11 | B15: Khâu tính tiền | C15: Màn Khoán theo kỳ (quy đổi, nhân giá, chia, ra tiền) | D15: =IF(E15>=1,"Đã xong",IF(E15>=0.8,"Gần xong",IF(E15=0,"Chưa làm","Làm dở"))) -> Chưa làm | E15: 0 | F15: 5 | G15: Mắt xích trung tâm, chưa bắt đầu. Đây là việc chính còn lại.
A16: 12 | B16: Khâu tính tiền | C16: Trừ lỗi hàng hỏng vào tiền khoán | D16: =IF(E16>=1,"Đã xong",IF(E16>=0.8,"Gần xong",IF(E16=0,"Chưa làm","Làm dở"))) -> Làm dở | E16: 0.2 | F16: 1 | G16: Có sẵn luật trần khấu trừ 30%, chưa có nguồn số liệu.
... A23: 19 | B23: Khoán km lái xe | C23: Khoán km cho tài xế và phụ xe | D23: =IF(E23>=1,"Đã xong",IF(E23>=0.8,"Gần xong",IF(E23=0,"Chưa làm","Làm dở"))) -> Gần xong | E23: 0.9 | F23: 3 | G23: Km × đơn giá theo bậc xe × tỷ lệ tài xế, phụ xe; còn chỉnh nhỏ phần km về kho.
C24: TIẾN ĐỘ TÍNH LƯƠNG KHOÁN | D24: =IF(E24>=1,"Đã xong","Làm dở") -> Làm dở | E24: =SUMPRODUCT(E5:E23,F5:F23)/SUM(F5:F23) -> 0.55757576 | F24: =SUM(F5:F23) -> 33 | G24: Bình quân % các hạng mục theo trọng số (hạng mục càng nặng trọng số càng lớn).
A26: Theo khâu
B27: Khâu | C27: Số hạng mục | D27: % hoàn thành
B28: Đầu vào | C28: =COUNTIF($B$5:$B$23,B28) -> 6 | D28: =SUMPRODUCT(($B$5:$B$23=B28)*$E$5:$E$23*$F$5:$F$23)/SUMIF($B$5:$B$23,B28,$F$5:$F$23) -> 0.78888889
B29: Khâu tính tiền | C29: =COUNTIF($B$5:$B$23,B29) -> 6 | D29: =SUMPRODUCT(($B$5:$B$23=B29)*$E$5:$E$23*$F$5:$F$23)/SUMIF($B$5:$B$23,B29,$F$5:$F$23) -> 0.15384615
B30: Đầu ra lương | C30: =COUNTIF($B$5:$B$23,B30) -> 6 | D30: =SUMPRODUCT(($B$5:$B$23=B30)*$E$5:$E$23*$F$5:$F$23)/SUMIF($B$5:$B$23,B30,$F$5:$F$23) -> 0.825
B31: Khoán km lái xe | C31: =COUNTIF($B$5:$B$23,B31) -> 1 | D31: =SUMPRODUCT(($B$5:$B$23=B31)*$E$5:$E$23*$F$5:$F$23)/SUMIF($B$5:$B$23,B31,$F$5:$F$23) -> 0.9
A33: Việc cần làm để hoàn thành
B34: 1 | C34: Dựng màn Khoán theo kỳ cho kế toán lương: lấy sản lượng các mẻ trong kỳ, quy đổi đơn vị, nhân đơn giá, chia cho từng người tham gia.
B35: 2 | C35: Nối kết quả màn này vào cột Khoán SP của bảng lương (hiện đang bằng 0 với mọi người).
B36: 3 | C36: Đưa thưởng hoặc ăn chia của tổ trưởng, chỉ tiêu ngày và khoản trừ lỗi hàng hỏng vào tiền khoán.
B37: 4 | C37: Thêm bước duyệt sản lượng khoán trước khi chốt kỳ lương; thêm xuất Excel bảng sản lượng tổ.
B38: 5 | C38: Chốt một luật còn vênh: đơn giá lấy theo lúc ghi mẻ hay theo bảng giá lúc tính lương.
B39: 6 | C39: Cập nhật tài liệu hướng dẫn tính lương (đang tả cách làm cũ trước 18/09).
A41: Không tính vào tiến độ
B42: – | C42: Báo cáo năng suất theo người, tổ, máy | D42: Chưa làm; không bắt buộc để trả được lương khoán.
B43: – | C43: Khoản khoán không gắn sản lượng (máy hư, hết hàng…) | D43: Thiết kế 11/09 xếp vào mục Không làm.
A45: Trong lúc chưa có màn Khoán theo kỳ, người ở tổ khoán đang được trả theo lương bù lỗ (tính theo công), không có tiền giờ tăng ca.

Sheet Tính năng chung
A1: TÍNH NĂNG CHUNG CỦA HỆ THỐNG
A2: Có sẵn ở nhiều phân hệ, không tính riêng vào % từng phân hệ.
A4: STT | B4: Tính năng | C4: Mô tả
A5: 1 | B5: Thông báo tức thời | C5: Duyệt hoặc từ chối báo giá, đơn đủ cọc, việc mới xuống tổ, bàn giao cần xác nhận, KCS bắt lỗi, kho đã nhận, chuyến giao, nhắc hẹn chăm sóc khách. Bảng tự cập nhật, không cần tải lại trang.
A6: 2 | B6: Phân quyền theo từng màn | C6: Người dùng chỉ thấy màn và dữ liệu được cấp; quyền xem tiền và giá vốn gác ở máy chủ.
A7: 3 | B7: Nhật ký thao tác | C7: Mọi phiếu, lệnh, danh mục đều lưu ai sửa gì, lúc nào.
A8: 4 | B8: Nhập và xuất Excel | C8: 9 danh mục nhập xuất Excel; các báo cáo, bảng lương, bảng công, tạm ứng, khấu hao, khách hàng xuất Excel; báo cáo kho và công nợ theo mẫu MISA.
A9: 5 | B9: In phiếu theo mẫu | C9: Báo giá trên giấy tiêu đề, phiếu thu 01-TT, phiếu chi 02-TT, phiếu xuất kho và giao hàng mẫu MISA, phiếu bảo trì, phiếu lương, tem lô.
A10: 6 | B10: Dùng trên điện thoại | C10: Bàn việc của tổ, chấm công GPS, phiếu bảo trì, giao hàng dùng được trên điện thoại.
A11: 7 | B11: Xóa an toàn | C11: Mục đã dùng thì chỉ chuyển Ngừng dùng, không mất chứng từ cũ.
